2023-05-12 07:41:01,181 ERROR: Exception on / [GET] [in /home/t1/PycharmProjects/flask_car_testdrive/venv/lib/python3.11/site-packages/flask/app.py:1744]
Traceback (most recent call last):
  File "/home/t1/PycharmProjects/flask_car_testdrive/venv/lib/python3.11/site-packages/flask/app.py", line 2528, in wsgi_app
    response = self.full_dispatch_request()
               ^^^^^^^^^^^^^^^^^^^^^^^^^^^^
  File "/home/t1/PycharmProjects/flask_car_testdrive/venv/lib/python3.11/site-packages/flask/app.py", line 1825, in full_dispatch_request
    rv = self.handle_user_exception(e)
         ^^^^^^^^^^^^^^^^^^^^^^^^^^^^^
  File "/home/t1/PycharmProjects/flask_car_testdrive/venv/lib/python3.11/site-packages/flask/app.py", line 1823, in full_dispatch_request
    rv = self.dispatch_request()
         ^^^^^^^^^^^^^^^^^^^^^^^
  File "/home/t1/PycharmProjects/flask_car_testdrive/venv/lib/python3.11/site-packages/flask/app.py", line 1799, in dispatch_request
    return self.ensure_sync(self.view_functions[rule.endpoint])(**view_args)
           ^^^^^^^^^^^^^^^^^^^^^^^^^^^^^^^^^^^^^^^^^^^^^^^^^^^^^^^^^^^^^^^^^
  File "/home/t1/PycharmProjects/flask_car_testdrive/main.py", line 24, in index
    mail.send(msg)
  File "/home/t1/PycharmProjects/flask_car_testdrive/venv/lib/python3.11/site-packages/flask_mail.py", line 492, in send
    message.send(connection)
  File "/home/t1/PycharmProjects/flask_car_testdrive/venv/lib/python3.11/site-packages/flask_mail.py", line 427, in send
    connection.send(self)
  File "/home/t1/PycharmProjects/flask_car_testdrive/venv/lib/python3.11/site-packages/flask_mail.py", line 181, in send
    if message.has_bad_headers():
       ^^^^^^^^^^^^^^^^^^^^^^^^^
  File "/home/t1/PycharmProjects/flask_car_testdrive/venv/lib/python3.11/site-packages/flask_mail.py", line 400, in has_bad_headers
    headers = [self.sender, self.reply_to] + self.recipients
              ~~~~~~~~~~~~~~~~~~~~~~~~~~~~~^~~~~~~~~~~~~~~~~
TypeError: can only concatenate list (not "str") to list
2023-05-12 07:41:14,929 INFO: Start application [in /home/t1/PycharmProjects/flask_car_testdrive/app/__init__.py:56]
2023-05-12 07:41:16,305 ERROR: Exception on / [GET] [in /home/t1/PycharmProjects/flask_car_testdrive/venv/lib/python3.11/site-packages/flask/app.py:1744]
Traceback (most recent call last):
  File "/home/t1/PycharmProjects/flask_car_testdrive/venv/lib/python3.11/site-packages/flask/app.py", line 2528, in wsgi_app
    response = self.full_dispatch_request()
               ^^^^^^^^^^^^^^^^^^^^^^^^^^^^
  File "/home/t1/PycharmProjects/flask_car_testdrive/venv/lib/python3.11/site-packages/flask/app.py", line 1825, in full_dispatch_request
    rv = self.handle_user_exception(e)
         ^^^^^^^^^^^^^^^^^^^^^^^^^^^^^
  File "/home/t1/PycharmProjects/flask_car_testdrive/venv/lib/python3.11/site-packages/flask/app.py", line 1823, in full_dispatch_request
    rv = self.dispatch_request()
         ^^^^^^^^^^^^^^^^^^^^^^^
  File "/home/t1/PycharmProjects/flask_car_testdrive/venv/lib/python3.11/site-packages/flask/app.py", line 1799, in dispatch_request
    return self.ensure_sync(self.view_functions[rule.endpoint])(**view_args)
           ^^^^^^^^^^^^^^^^^^^^^^^^^^^^^^^^^^^^^^^^^^^^^^^^^^^^^^^^^^^^^^^^^
  File "/home/t1/PycharmProjects/flask_car_testdrive/main.py", line 24, in index
    mail.send(msg)
  File "/home/t1/PycharmProjects/flask_car_testdrive/venv/lib/python3.11/site-packages/flask_mail.py", line 492, in send
    message.send(connection)
  File "/home/t1/PycharmProjects/flask_car_testdrive/venv/lib/python3.11/site-packages/flask_mail.py", line 427, in send
    connection.send(self)
  File "/home/t1/PycharmProjects/flask_car_testdrive/venv/lib/python3.11/site-packages/flask_mail.py", line 181, in send
    if message.has_bad_headers():
       ^^^^^^^^^^^^^^^^^^^^^^^^^
  File "/home/t1/PycharmProjects/flask_car_testdrive/venv/lib/python3.11/site-packages/flask_mail.py", line 400, in has_bad_headers
    headers = [self.sender, self.reply_to] + self.recipients
              ~~~~~~~~~~~~~~~~~~~~~~~~~~~~~^~~~~~~~~~~~~~~~~
TypeError: can only concatenate list (not "str") to list
2023-05-12 07:41:19,461 ERROR: Exception on / [GET] [in /home/t1/PycharmProjects/flask_car_testdrive/venv/lib/python3.11/site-packages/flask/app.py:1744]
Traceback (most recent call last):
  File "/home/t1/PycharmProjects/flask_car_testdrive/venv/lib/python3.11/site-packages/flask/app.py", line 2528, in wsgi_app
    response = self.full_dispatch_request()
               ^^^^^^^^^^^^^^^^^^^^^^^^^^^^
  File "/home/t1/PycharmProjects/flask_car_testdrive/venv/lib/python3.11/site-packages/flask/app.py", line 1825, in full_dispatch_request
    rv = self.handle_user_exception(e)
         ^^^^^^^^^^^^^^^^^^^^^^^^^^^^^
  File "/home/t1/PycharmProjects/flask_car_testdrive/venv/lib/python3.11/site-packages/flask/app.py", line 1823, in full_dispatch_request
    rv = self.dispatch_request()
         ^^^^^^^^^^^^^^^^^^^^^^^
  File "/home/t1/PycharmProjects/flask_car_testdrive/venv/lib/python3.11/site-packages/flask/app.py", line 1799, in dispatch_request
    return self.ensure_sync(self.view_functions[rule.endpoint])(**view_args)
           ^^^^^^^^^^^^^^^^^^^^^^^^^^^^^^^^^^^^^^^^^^^^^^^^^^^^^^^^^^^^^^^^^
  File "/home/t1/PycharmProjects/flask_car_testdrive/main.py", line 24, in index
    mail.send(msg)
  File "/home/t1/PycharmProjects/flask_car_testdrive/venv/lib/python3.11/site-packages/flask_mail.py", line 492, in send
    message.send(connection)
  File "/home/t1/PycharmProjects/flask_car_testdrive/venv/lib/python3.11/site-packages/flask_mail.py", line 427, in send
    connection.send(self)
  File "/home/t1/PycharmProjects/flask_car_testdrive/venv/lib/python3.11/site-packages/flask_mail.py", line 181, in send
    if message.has_bad_headers():
       ^^^^^^^^^^^^^^^^^^^^^^^^^
  File "/home/t1/PycharmProjects/flask_car_testdrive/venv/lib/python3.11/site-packages/flask_mail.py", line 400, in has_bad_headers
    headers = [self.sender, self.reply_to] + self.recipients
              ~~~~~~~~~~~~~~~~~~~~~~~~~~~~~^~~~~~~~~~~~~~~~~
TypeError: can only concatenate list (not "str") to list
2023-05-12 07:52:46,438 INFO: Start application [in /home/t1/PycharmProjects/flask_car_testdrive/app/__init__.py:56]
2023-05-12 07:52:49,853 ERROR: Exception on / [GET] [in /home/t1/PycharmProjects/flask_car_testdrive/venv/lib/python3.11/site-packages/flask/app.py:1744]
Traceback (most recent call last):
  File "/home/t1/PycharmProjects/flask_car_testdrive/venv/lib/python3.11/site-packages/flask/app.py", line 2528, in wsgi_app
    response = self.full_dispatch_request()
               ^^^^^^^^^^^^^^^^^^^^^^^^^^^^
  File "/home/t1/PycharmProjects/flask_car_testdrive/venv/lib/python3.11/site-packages/flask/app.py", line 1825, in full_dispatch_request
    rv = self.handle_user_exception(e)
         ^^^^^^^^^^^^^^^^^^^^^^^^^^^^^
  File "/home/t1/PycharmProjects/flask_car_testdrive/venv/lib/python3.11/site-packages/flask/app.py", line 1823, in full_dispatch_request
    rv = self.dispatch_request()
         ^^^^^^^^^^^^^^^^^^^^^^^
  File "/home/t1/PycharmProjects/flask_car_testdrive/venv/lib/python3.11/site-packages/flask/app.py", line 1799, in dispatch_request
    return self.ensure_sync(self.view_functions[rule.endpoint])(**view_args)
           ^^^^^^^^^^^^^^^^^^^^^^^^^^^^^^^^^^^^^^^^^^^^^^^^^^^^^^^^^^^^^^^^^
  File "/home/t1/PycharmProjects/flask_car_testdrive/main.py", line 24, in index
    mail.send(msg)
  File "/home/t1/PycharmProjects/flask_car_testdrive/venv/lib/python3.11/site-packages/flask_mail.py", line 492, in send
    message.send(connection)
  File "/home/t1/PycharmProjects/flask_car_testdrive/venv/lib/python3.11/site-packages/flask_mail.py", line 427, in send
    connection.send(self)
  File "/home/t1/PycharmProjects/flask_car_testdrive/venv/lib/python3.11/site-packages/flask_mail.py", line 181, in send
    if message.has_bad_headers():
       ^^^^^^^^^^^^^^^^^^^^^^^^^
  File "/home/t1/PycharmProjects/flask_car_testdrive/venv/lib/python3.11/site-packages/flask_mail.py", line 400, in has_bad_headers
    headers = [self.sender, self.reply_to] + self.recipients
              ~~~~~~~~~~~~~~~~~~~~~~~~~~~~~^~~~~~~~~~~~~~~~~
TypeError: can only concatenate list (not "str") to list
2023-05-12 07:53:50,169 INFO: Start application [in /home/t1/PycharmProjects/flask_car_testdrive/app/__init__.py:56]
