2023-05-12 07:22:50,000 ERROR: Exception on / [GET] [in /home/t1/PycharmProjects/flask_car_testdrive/venv/lib/python3.11/site-packages/flask/app.py:1744]
Traceback (most recent call last):
  File "/home/t1/PycharmProjects/flask_car_testdrive/venv/lib/python3.11/site-packages/flask/app.py", line 2528, in wsgi_app
    response = self.full_dispatch_request()
               ^^^^^^^^^^^^^^^^^^^^^^^^^^^^
  File "/home/t1/PycharmProjects/flask_car_testdrive/venv/lib/python3.11/site-packages/flask/app.py", line 1825, in full_dispatch_request
    rv = self.handle_user_exception(e)
         ^^^^^^^^^^^^^^^^^^^^^^^^^^^^^
  File "/home/t1/PycharmProjects/flask_car_testdrive/venv/lib/python3.11/site-packages/flask/app.py", line 1823, in full_dispatch_request
    rv = self.dispatch_request()
         ^^^^^^^^^^^^^^^^^^^^^^^
  File "/home/t1/PycharmProjects/flask_car_testdrive/venv/lib/python3.11/site-packages/flask/app.py", line 1799, in dispatch_request
    return self.ensure_sync(self.view_functions[rule.endpoint])(**view_args)
           ^^^^^^^^^^^^^^^^^^^^^^^^^^^^^^^^^^^^^^^^^^^^^^^^^^^^^^^^^^^^^^^^^
  File "/home/t1/PycharmProjects/flask_car_testdrive/main.py", line 24, in index
    mail.send(msg)
  File "/home/t1/PycharmProjects/flask_car_testdrive/venv/lib/python3.11/site-packages/flask_mail.py", line 492, in send
    message.send(connection)
  File "/home/t1/PycharmProjects/flask_car_testdrive/venv/lib/python3.11/site-packages/flask_mail.py", line 427, in send
    connection.send(self)
  File "/home/t1/PycharmProjects/flask_car_testdrive/venv/lib/python3.11/site-packages/flask_mail.py", line 181, in send
    if message.has_bad_headers():
       ^^^^^^^^^^^^^^^^^^^^^^^^^
  File "/home/t1/PycharmProjects/flask_car_testdrive/venv/lib/python3.11/site-packages/flask_mail.py", line 400, in has_bad_headers
    headers = [self.sender, self.reply_to] + self.recipients
              ~~~~~~~~~~~~~~~~~~~~~~~~~~~~~^~~~~~~~~~~~~~~~~
TypeError: can only concatenate list (not "str") to list
2023-05-12 07:24:35,599 INFO: Start application [in /home/t1/PycharmProjects/flask_car_testdrive/app/__init__.py:55]
2023-05-12 07:24:37,886 ERROR: Exception on / [GET] [in /home/t1/PycharmProjects/flask_car_testdrive/venv/lib/python3.11/site-packages/flask/app.py:1744]
Traceback (most recent call last):
  File "/home/t1/PycharmProjects/flask_car_testdrive/venv/lib/python3.11/site-packages/flask/app.py", line 2528, in wsgi_app
    response = self.full_dispatch_request()
               ^^^^^^^^^^^^^^^^^^^^^^^^^^^^
  File "/home/t1/PycharmProjects/flask_car_testdrive/venv/lib/python3.11/site-packages/flask/app.py", line 1825, in full_dispatch_request
    rv = self.handle_user_exception(e)
         ^^^^^^^^^^^^^^^^^^^^^^^^^^^^^
  File "/home/t1/PycharmProjects/flask_car_testdrive/venv/lib/python3.11/site-packages/flask/app.py", line 1823, in full_dispatch_request
    rv = self.dispatch_request()
         ^^^^^^^^^^^^^^^^^^^^^^^
  File "/home/t1/PycharmProjects/flask_car_testdrive/venv/lib/python3.11/site-packages/flask/app.py", line 1799, in dispatch_request
    return self.ensure_sync(self.view_functions[rule.endpoint])(**view_args)
           ^^^^^^^^^^^^^^^^^^^^^^^^^^^^^^^^^^^^^^^^^^^^^^^^^^^^^^^^^^^^^^^^^
  File "/home/t1/PycharmProjects/flask_car_testdrive/main.py", line 25, in index
    mail.send(msg)
  File "/home/t1/PycharmProjects/flask_car_testdrive/venv/lib/python3.11/site-packages/flask_mail.py", line 492, in send
    message.send(connection)
  File "/home/t1/PycharmProjects/flask_car_testdrive/venv/lib/python3.11/site-packages/flask_mail.py", line 427, in send
    connection.send(self)
  File "/home/t1/PycharmProjects/flask_car_testdrive/venv/lib/python3.11/site-packages/flask_mail.py", line 181, in send
    if message.has_bad_headers():
       ^^^^^^^^^^^^^^^^^^^^^^^^^
  File "/home/t1/PycharmProjects/flask_car_testdrive/venv/lib/python3.11/site-packages/flask_mail.py", line 400, in has_bad_headers
    headers = [self.sender, self.reply_to] + self.recipients
              ~~~~~~~~~~~~~~~~~~~~~~~~~~~~~^~~~~~~~~~~~~~~~~
TypeError: can only concatenate list (not "str") to list
2023-05-12 07:25:06,146 INFO: Start application [in /home/t1/PycharmProjects/flask_car_testdrive/app/__init__.py:55]
2023-05-12 07:25:09,004 ERROR: Exception on / [GET] [in /home/t1/PycharmProjects/flask_car_testdrive/venv/lib/python3.11/site-packages/flask/app.py:1744]
Traceback (most recent call last):
  File "/home/t1/PycharmProjects/flask_car_testdrive/venv/lib/python3.11/site-packages/flask/app.py", line 2528, in wsgi_app
    response = self.full_dispatch_request()
               ^^^^^^^^^^^^^^^^^^^^^^^^^^^^
  File "/home/t1/PycharmProjects/flask_car_testdrive/venv/lib/python3.11/site-packages/flask/app.py", line 1825, in full_dispatch_request
    rv = self.handle_user_exception(e)
         ^^^^^^^^^^^^^^^^^^^^^^^^^^^^^
  File "/home/t1/PycharmProjects/flask_car_testdrive/venv/lib/python3.11/site-packages/flask/app.py", line 1823, in full_dispatch_request
    rv = self.dispatch_request()
         ^^^^^^^^^^^^^^^^^^^^^^^
  File "/home/t1/PycharmProjects/flask_car_testdrive/venv/lib/python3.11/site-packages/flask/app.py", line 1799, in dispatch_request
    return self.ensure_sync(self.view_functions[rule.endpoint])(**view_args)
           ^^^^^^^^^^^^^^^^^^^^^^^^^^^^^^^^^^^^^^^^^^^^^^^^^^^^^^^^^^^^^^^^^
  File "/home/t1/PycharmProjects/flask_car_testdrive/main.py", line 25, in index
    mail.send(msg)
  File "/home/t1/PycharmProjects/flask_car_testdrive/venv/lib/python3.11/site-packages/flask_mail.py", line 492, in send
    message.send(connection)
  File "/home/t1/PycharmProjects/flask_car_testdrive/venv/lib/python3.11/site-packages/flask_mail.py", line 427, in send
    connection.send(self)
  File "/home/t1/PycharmProjects/flask_car_testdrive/venv/lib/python3.11/site-packages/flask_mail.py", line 188, in send
    self.host.sendmail(sanitize_address(envelope_from or message.sender),
  File "/usr/lib/python3.11/smtplib.py", line 901, in sendmail
    raise SMTPRecipientsRefused(senderrs)
smtplib.SMTPRecipientsRefused: {'': (555, b'5.5.2 Syntax error. f16-20020ac251b0000000b004eed68a68efsm1336341lfk.280 - gsmtp')}
2023-05-12 07:30:38,401 INFO: Start application [in /home/t1/PycharmProjects/flask_car_testdrive/app/__init__.py:67]
2023-05-12 07:30:40,522 ERROR: Exception on / [GET] [in /home/t1/PycharmProjects/flask_car_testdrive/venv/lib/python3.11/site-packages/flask/app.py:1744]
Traceback (most recent call last):
  File "/home/t1/PycharmProjects/flask_car_testdrive/venv/lib/python3.11/site-packages/flask/app.py", line 2528, in wsgi_app
    response = self.full_dispatch_request()
               ^^^^^^^^^^^^^^^^^^^^^^^^^^^^
  File "/home/t1/PycharmProjects/flask_car_testdrive/venv/lib/python3.11/site-packages/flask/app.py", line 1825, in full_dispatch_request
    rv = self.handle_user_exception(e)
         ^^^^^^^^^^^^^^^^^^^^^^^^^^^^^
  File "/home/t1/PycharmProjects/flask_car_testdrive/venv/lib/python3.11/site-packages/flask/app.py", line 1823, in full_dispatch_request
    rv = self.dispatch_request()
         ^^^^^^^^^^^^^^^^^^^^^^^
  File "/home/t1/PycharmProjects/flask_car_testdrive/venv/lib/python3.11/site-packages/flask/app.py", line 1799, in dispatch_request
    return self.ensure_sync(self.view_functions[rule.endpoint])(**view_args)
           ^^^^^^^^^^^^^^^^^^^^^^^^^^^^^^^^^^^^^^^^^^^^^^^^^^^^^^^^^^^^^^^^^
  File "/home/t1/PycharmProjects/flask_car_testdrive/main.py", line 25, in index
    mail.send(msg)
  File "/home/t1/PycharmProjects/flask_car_testdrive/venv/lib/python3.11/site-packages/flask_mail.py", line 492, in send
    message.send(connection)
  File "/home/t1/PycharmProjects/flask_car_testdrive/venv/lib/python3.11/site-packages/flask_mail.py", line 427, in send
    connection.send(self)
  File "/home/t1/PycharmProjects/flask_car_testdrive/venv/lib/python3.11/site-packages/flask_mail.py", line 188, in send
    self.host.sendmail(sanitize_address(envelope_from or message.sender),
  File "/usr/lib/python3.11/smtplib.py", line 901, in sendmail
    raise SMTPRecipientsRefused(senderrs)
smtplib.SMTPRecipientsRefused: {'': (555, b'5.5.2 Syntax error. g9-20020a2eb0c9000000b002ac8164d77fsm2618842ljl.86 - gsmtp')}
2023-05-12 07:30:47,525 ERROR: Exception on / [GET] [in /home/t1/PycharmProjects/flask_car_testdrive/venv/lib/python3.11/site-packages/flask/app.py:1744]
Traceback (most recent call last):
  File "/home/t1/PycharmProjects/flask_car_testdrive/venv/lib/python3.11/site-packages/flask/app.py", line 2528, in wsgi_app
    response = self.full_dispatch_request()
               ^^^^^^^^^^^^^^^^^^^^^^^^^^^^
  File "/home/t1/PycharmProjects/flask_car_testdrive/venv/lib/python3.11/site-packages/flask/app.py", line 1825, in full_dispatch_request
    rv = self.handle_user_exception(e)
         ^^^^^^^^^^^^^^^^^^^^^^^^^^^^^
  File "/home/t1/PycharmProjects/flask_car_testdrive/venv/lib/python3.11/site-packages/flask/app.py", line 1823, in full_dispatch_request
    rv = self.dispatch_request()
         ^^^^^^^^^^^^^^^^^^^^^^^
  File "/home/t1/PycharmProjects/flask_car_testdrive/venv/lib/python3.11/site-packages/flask/app.py", line 1799, in dispatch_request
    return self.ensure_sync(self.view_functions[rule.endpoint])(**view_args)
           ^^^^^^^^^^^^^^^^^^^^^^^^^^^^^^^^^^^^^^^^^^^^^^^^^^^^^^^^^^^^^^^^^
  File "/home/t1/PycharmProjects/flask_car_testdrive/main.py", line 25, in index
    mail.send(msg)
  File "/home/t1/PycharmProjects/flask_car_testdrive/venv/lib/python3.11/site-packages/flask_mail.py", line 492, in send
    message.send(connection)
  File "/home/t1/PycharmProjects/flask_car_testdrive/venv/lib/python3.11/site-packages/flask_mail.py", line 427, in send
    connection.send(self)
  File "/home/t1/PycharmProjects/flask_car_testdrive/venv/lib/python3.11/site-packages/flask_mail.py", line 188, in send
    self.host.sendmail(sanitize_address(envelope_from or message.sender),
  File "/usr/lib/python3.11/smtplib.py", line 901, in sendmail
    raise SMTPRecipientsRefused(senderrs)
smtplib.SMTPRecipientsRefused: {'': (555, b'5.5.2 Syntax error. i15-20020a2e864f000000b002a777ec77dcsm2645758ljj.34 - gsmtp')}
